[2023-11-08T14:32:37.681+0000] {taskinstance.py:1159} INFO - Dependencies all met for dep_context=non-requeueable deps ti=<TaskInstance: sql_hook_to_s3.load_data_from_pg_to_s3 scheduled__2023-11-08T03:30:00+00:00 [queued]>
[2023-11-08T14:32:37.706+0000] {taskinstance.py:1159} INFO - Dependencies all met for dep_context=requeueable deps ti=<TaskInstance: sql_hook_to_s3.load_data_from_pg_to_s3 scheduled__2023-11-08T03:30:00+00:00 [queued]>
[2023-11-08T14:32:37.708+0000] {taskinstance.py:1361} INFO - Starting attempt 1 of 6
[2023-11-08T14:32:37.736+0000] {taskinstance.py:1382} INFO - Executing <Task(PythonOperator): load_data_from_pg_to_s3> on 2023-11-08 03:30:00+00:00
[2023-11-08T14:32:37.744+0000] {standard_task_runner.py:57} INFO - Started process 282 to run task
[2023-11-08T14:32:37.752+0000] {standard_task_runner.py:84} INFO - Running: ['***', 'tasks', 'run', 'sql_hook_to_s3', 'load_data_from_pg_to_s3', 'scheduled__2023-11-08T03:30:00+00:00', '--job-id', '86', '--raw', '--subdir', 'DAGS_FOLDER/sql_hook_to_s3_dag.py', '--cfg-path', '/tmp/tmpnq4_8b3x']
[2023-11-08T14:32:37.759+0000] {standard_task_runner.py:85} INFO - Job 86: Subtask load_data_from_pg_to_s3
[2023-11-08T14:32:37.863+0000] {task_command.py:416} INFO - Running <TaskInstance: sql_hook_to_s3.load_data_from_pg_to_s3 scheduled__2023-11-08T03:30:00+00:00 [running]> on host 5cb9101badf1
[2023-11-08T14:32:38.030+0000] {taskinstance.py:1662} INFO - Exporting env vars: AIRFLOW_CTX_DAG_EMAIL='safarnejad.ho@gmail.com' AIRFLOW_CTX_DAG_OWNER='safarnejad' AIRFLOW_CTX_DAG_ID='sql_hook_to_s3' AIRFLOW_CTX_TASK_ID='load_data_from_pg_to_s3' AIRFLOW_CTX_EXECUTION_DATE='2023-11-08T03:30:00+00:00' AIRFLOW_CTX_TRY_NUMBER='1' AIRFLOW_CTX_DAG_RUN_ID='scheduled__2023-11-08T03:30:00+00:00'
[2023-11-08T14:32:38.050+0000] {base.py:73} INFO - Using connection ID 'orders-pg-conn' for task execution.
[2023-11-08T14:32:38.062+0000] {taskinstance.py:1937} ERROR - Task failed with exception
Traceback (most recent call last):
  File "/home/airflow/.local/lib/python3.8/site-packages/airflow/operators/python.py", line 192, in execute
    return_value = self.execute_callable()
  File "/home/airflow/.local/lib/python3.8/site-packages/airflow/operators/python.py", line 209, in execute_callable
    return self.python_callable(*self.op_args, **self.op_kwargs)
  File "/opt/airflow/dags/sql_hook_to_s3_dag.py", line 24, in load_data_to_file
    cursor = hook.get_conn().cursor()
  File "/home/airflow/.local/lib/python3.8/site-packages/airflow/providers/postgres/hooks/postgres.py", line 155, in get_conn
    self.conn = psycopg2.connect(**conn_args)
  File "/home/airflow/.local/lib/python3.8/site-packages/psycopg2/__init__.py", line 122, in connect
    conn = _connect(dsn, connection_factory=connection_factory, **kwasync)
psycopg2.OperationalError: could not translate host name "host.docker.internals" to address: Name or service not known

[2023-11-08T14:32:38.081+0000] {taskinstance.py:1400} INFO - Marking task as UP_FOR_RETRY. dag_id=sql_hook_to_s3, task_id=load_data_from_pg_to_s3, execution_date=20231108T033000, start_date=20231108T143237, end_date=20231108T143238
[2023-11-08T14:32:38.098+0000] {standard_task_runner.py:104} ERROR - Failed to execute job 86 for task load_data_from_pg_to_s3 (could not translate host name "host.docker.internals" to address: Name or service not known
; 282)
[2023-11-08T14:32:38.128+0000] {local_task_job_runner.py:228} INFO - Task exited with return code 1
[2023-11-08T14:32:38.158+0000] {taskinstance.py:2778} INFO - 0 downstream tasks scheduled from follow-on schedule check
