[2023-11-07 10:29:23,977] {taskinstance.py:1035} INFO - Dependencies all met for <TaskInstance: external_package_dag.test_import_scikit_learn manual__2023-11-07T10:29:22.534602+00:00 [queued]>
[2023-11-07 10:29:24,010] {taskinstance.py:1035} INFO - Dependencies all met for <TaskInstance: external_package_dag.test_import_scikit_learn manual__2023-11-07T10:29:22.534602+00:00 [queued]>
[2023-11-07 10:29:24,014] {taskinstance.py:1241} INFO - 
--------------------------------------------------------------------------------
[2023-11-07 10:29:24,014] {taskinstance.py:1242} INFO - Starting attempt 1 of 3
[2023-11-07 10:29:24,015] {taskinstance.py:1243} INFO - 
--------------------------------------------------------------------------------
[2023-11-07 10:29:24,034] {taskinstance.py:1262} INFO - Executing <Task(_PythonDecoratedOperator): test_import_scikit_learn> on 2023-11-07 10:29:22.534602+00:00
[2023-11-07 10:29:24,040] {standard_task_runner.py:52} INFO - Started process 961 to run task
[2023-11-07 10:29:24,045] {standard_task_runner.py:76} INFO - Running: ['***', 'tasks', 'run', 'external_package_dag', 'test_import_scikit_learn', 'manual__2023-11-07T10:29:22.534602+00:00', '--job-id', '358', '--raw', '--subdir', 'DAGS_FOLDER/external_package_dag.py', '--cfg-path', '/tmp/tmph3b_9awf', '--error-file', '/tmp/tmphwluh0ve']
[2023-11-07 10:29:24,047] {standard_task_runner.py:77} INFO - Job 358: Subtask test_import_scikit_learn
[2023-11-07 10:29:24,118] {logging_mixin.py:109} INFO - Running <TaskInstance: external_package_dag.test_import_scikit_learn manual__2023-11-07T10:29:22.534602+00:00 [running]> on host 108321174b30
[2023-11-07 10:29:24,145] {taskinstance.py:1035} INFO - Dependencies all met for <TaskInstance: external_package_dag.test_import_scikit_learn scheduled__2023-11-06T00:00:00+00:00 [queued]>
[2023-11-07 10:29:24,163] {taskinstance.py:1686} ERROR - Task failed with exception
Traceback (most recent call last):
  File "/home/airflow/.local/lib/python3.8/site-packages/sqlalchemy/engine/base.py", line 1276, in _execute_context
    self.dialect.do_execute(
  File "/home/airflow/.local/lib/python3.8/site-packages/sqlalchemy/engine/default.py", line 608, in do_execute
    cursor.execute(statement, parameters)
psycopg2.errors.UndefinedColumn: column xcom.execution_date does not exist
LINE 1: ...AND xcom.task_id = 'test_import_scikit_learn' AND xcom.execu...
                                                             ^


The above exception was the direct cause of the following exception:

Traceback (most recent call last):
  File "/home/airflow/.local/lib/python3.8/site-packages/airflow/models/taskinstance.py", line 1324, in _run_raw_task
    self._execute_task_with_callbacks(context)
  File "/home/airflow/.local/lib/python3.8/site-packages/airflow/models/taskinstance.py", line 1403, in _execute_task_with_callbacks
    self.clear_xcom_data()
  File "/home/airflow/.local/lib/python3.8/site-packages/airflow/utils/session.py", line 70, in wrapper
    return func(*args, session=session, **kwargs)
  File "/home/airflow/.local/lib/python3.8/site-packages/airflow/models/taskinstance.py", line 791, in clear_xcom_data
    XCom.clear(
  File "/home/airflow/.local/lib/python3.8/site-packages/airflow/utils/session.py", line 67, in wrapper
    return func(*args, **kwargs)
  File "/home/airflow/.local/lib/python3.8/site-packages/airflow/models/xcom.py", line 322, in clear
    return query.delete()
  File "/home/airflow/.local/lib/python3.8/site-packages/sqlalchemy/orm/query.py", line 3926, in delete
    delete_op.exec_()
  File "/home/airflow/.local/lib/python3.8/site-packages/sqlalchemy/orm/persistence.py", line 1697, in exec_
    self._do_exec()
  File "/home/airflow/.local/lib/python3.8/site-packages/sqlalchemy/orm/persistence.py", line 1930, in _do_exec
    self._execute_stmt(delete_stmt)
  File "/home/airflow/.local/lib/python3.8/site-packages/sqlalchemy/orm/persistence.py", line 1702, in _execute_stmt
    self.result = self.query._execute_crud(stmt, self.mapper)
  File "/home/airflow/.local/lib/python3.8/site-packages/sqlalchemy/orm/query.py", line 3568, in _execute_crud
    return conn.execute(stmt, self._params)
  File "/home/airflow/.local/lib/python3.8/site-packages/sqlalchemy/engine/base.py", line 1011, in execute
    return meth(self, multiparams, params)
  File "/home/airflow/.local/lib/python3.8/site-packages/sqlalchemy/sql/elements.py", line 298, in _execute_on_connection
    return connection._execute_clauseelement(self, multiparams, params)
  File "/home/airflow/.local/lib/python3.8/site-packages/sqlalchemy/engine/base.py", line 1124, in _execute_clauseelement
    ret = self._execute_context(
  File "/home/airflow/.local/lib/python3.8/site-packages/sqlalchemy/engine/base.py", line 1316, in _execute_context
    self._handle_dbapi_exception(
  File "/home/airflow/.local/lib/python3.8/site-packages/sqlalchemy/engine/base.py", line 1510, in _handle_dbapi_exception
    util.raise_(
  File "/home/airflow/.local/lib/python3.8/site-packages/sqlalchemy/util/compat.py", line 182, in raise_
    raise exception
  File "/home/airflow/.local/lib/python3.8/site-packages/sqlalchemy/engine/base.py", line 1276, in _execute_context
    self.dialect.do_execute(
  File "/home/airflow/.local/lib/python3.8/site-packages/sqlalchemy/engine/default.py", line 608, in do_execute
    cursor.execute(statement, parameters)
sqlalchemy.exc.ProgrammingError: (psycopg2.errors.UndefinedColumn) column xcom.execution_date does not exist
LINE 1: ...AND xcom.task_id = 'test_import_scikit_learn' AND xcom.execu...
                                                             ^

[SQL: DELETE FROM xcom WHERE xcom.dag_id = %(dag_id_1)s AND xcom.task_id = %(task_id_1)s AND xcom.execution_date = %(execution_date_1)s]
[parameters: {'dag_id_1': 'external_package_dag', 'task_id_1': 'test_import_scikit_learn', 'execution_date_1': datetime.datetime(2023, 11, 7, 10, 29, 22, 534602, tzinfo=Timezone('UTC'))}]
(Background on this error at: http://sqlalche.me/e/13/f405)
[2023-11-07 10:29:24,172] {taskinstance.py:1035} INFO - Dependencies all met for <TaskInstance: external_package_dag.test_import_scikit_learn scheduled__2023-11-06T00:00:00+00:00 [queued]>
[2023-11-07 10:29:24,172] {taskinstance.py:1241} INFO - 
--------------------------------------------------------------------------------
[2023-11-07 10:29:24,173] {taskinstance.py:1242} INFO - Starting attempt 1 of 3
[2023-11-07 10:29:24,174] {taskinstance.py:1243} INFO - 
--------------------------------------------------------------------------------
[2023-11-07 10:29:24,188] {taskinstance.py:1270} INFO - Marking task as UP_FOR_RETRY. dag_id=external_package_dag, task_id=test_import_scikit_learn, execution_date=20231107T102922, start_date=20231107T102923, end_date=20231107T102924
[2023-11-07 10:29:24,195] {taskinstance.py:1262} INFO - Executing <Task(_PythonDecoratedOperator): test_import_scikit_learn> on 2023-11-06 00:00:00+00:00
[2023-11-07 10:29:24,200] {standard_task_runner.py:52} INFO - Started process 964 to run task
[2023-11-07 10:29:24,204] {standard_task_runner.py:76} INFO - Running: ['***', 'tasks', 'run', 'external_package_dag', 'test_import_scikit_learn', 'scheduled__2023-11-06T00:00:00+00:00', '--job-id', '361', '--raw', '--subdir', 'DAGS_FOLDER/external_package_dag.py', '--cfg-path', '/tmp/tmpgbumxab6', '--error-file', '/tmp/tmpgzokfbkk']
[2023-11-07 10:29:24,201] {standard_task_runner.py:88} ERROR - Failed to execute job 358 for task test_import_scikit_learn
Traceback (most recent call last):
  File "/home/airflow/.local/lib/python3.8/site-packages/sqlalchemy/engine/base.py", line 1276, in _execute_context
    self.dialect.do_execute(
  File "/home/airflow/.local/lib/python3.8/site-packages/sqlalchemy/engine/default.py", line 608, in do_execute
    cursor.execute(statement, parameters)
psycopg2.errors.UndefinedColumn: column xcom.execution_date does not exist
LINE 1: ...AND xcom.task_id = 'test_import_scikit_learn' AND xcom.execu...
                                                             ^


The above exception was the direct cause of the following exception:

Traceback (most recent call last):
  File "/home/airflow/.local/lib/python3.8/site-packages/airflow/models/taskinstance.py", line 1324, in _run_raw_task
    self._execute_task_with_callbacks(context)
  File "/home/airflow/.local/lib/python3.8/site-packages/airflow/models/taskinstance.py", line 1403, in _execute_task_with_callbacks
    self.clear_xcom_data()
  File "/home/airflow/.local/lib/python3.8/site-packages/airflow/utils/session.py", line 70, in wrapper
    return func(*args, session=session, **kwargs)
  File "/home/airflow/.local/lib/python3.8/site-packages/airflow/models/taskinstance.py", line 791, in clear_xcom_data
    XCom.clear(
  File "/home/airflow/.local/lib/python3.8/site-packages/airflow/utils/session.py", line 67, in wrapper
    return func(*args, **kwargs)
  File "/home/airflow/.local/lib/python3.8/site-packages/airflow/models/xcom.py", line 322, in clear
    return query.delete()
  File "/home/airflow/.local/lib/python3.8/site-packages/sqlalchemy/orm/query.py", line 3926, in delete
    delete_op.exec_()
  File "/home/airflow/.local/lib/python3.8/site-packages/sqlalchemy/orm/persistence.py", line 1697, in exec_
    self._do_exec()
  File "/home/airflow/.local/lib/python3.8/site-packages/sqlalchemy/orm/persistence.py", line 1930, in _do_exec
    self._execute_stmt(delete_stmt)
  File "/home/airflow/.local/lib/python3.8/site-packages/sqlalchemy/orm/persistence.py", line 1702, in _execute_stmt
    self.result = self.query._execute_crud(stmt, self.mapper)
  File "/home/airflow/.local/lib/python3.8/site-packages/sqlalchemy/orm/query.py", line 3568, in _execute_crud
    return conn.execute(stmt, self._params)
  File "/home/airflow/.local/lib/python3.8/site-packages/sqlalchemy/engine/base.py", line 1011, in execute
    return meth(self, multiparams, params)
  File "/home/airflow/.local/lib/python3.8/site-packages/sqlalchemy/sql/elements.py", line 298, in _execute_on_connection
    return connection._execute_clauseelement(self, multiparams, params)
  File "/home/airflow/.local/lib/python3.8/site-packages/sqlalchemy/engine/base.py", line 1124, in _execute_clauseelement
    ret = self._execute_context(
  File "/home/airflow/.local/lib/python3.8/site-packages/sqlalchemy/engine/base.py", line 1316, in _execute_context
    self._handle_dbapi_exception(
  File "/home/airflow/.local/lib/python3.8/site-packages/sqlalchemy/engine/base.py", line 1510, in _handle_dbapi_exception
    util.raise_(
  File "/home/airflow/.local/lib/python3.8/site-packages/sqlalchemy/util/compat.py", line 182, in raise_
    raise exception
  File "/home/airflow/.local/lib/python3.8/site-packages/sqlalchemy/engine/base.py", line 1276, in _execute_context
    self.dialect.do_execute(
  File "/home/airflow/.local/lib/python3.8/site-packages/sqlalchemy/engine/default.py", line 608, in do_execute
    cursor.execute(statement, parameters)
sqlalchemy.exc.ProgrammingError: (psycopg2.errors.UndefinedColumn) column xcom.execution_date does not exist
LINE 1: ...AND xcom.task_id = 'test_import_scikit_learn' AND xcom.execu...
                                                             ^

[SQL: DELETE FROM xcom WHERE xcom.dag_id = %(dag_id_1)s AND xcom.task_id = %(task_id_1)s AND xcom.execution_date = %(execution_date_1)s]
[parameters: {'dag_id_1': 'external_package_dag', 'task_id_1': 'test_import_scikit_learn', 'execution_date_1': datetime.datetime(2023, 11, 7, 10, 29, 22, 534602, tzinfo=Timezone('UTC'))}]
(Background on this error at: http://sqlalche.me/e/13/f405)

During handling of the above exception, another exception occurred:

Traceback (most recent call last):
  File "/home/airflow/.local/lib/python3.8/site-packages/sqlalchemy/engine/base.py", line 1276, in _execute_context
    self.dialect.do_execute(
  File "/home/airflow/.local/lib/python3.8/site-packages/sqlalchemy/engine/default.py", line 608, in do_execute
    cursor.execute(statement, parameters)
psycopg2.errors.UndefinedColumn: column "execution_date" of relation "task_fail" does not exist
LINE 1: INSERT INTO task_fail (task_id, dag_id, execution_date, star...
                                                ^


The above exception was the direct cause of the following exception:

Traceback (most recent call last):
  File "/home/airflow/.local/lib/python3.8/site-packages/airflow/task/task_runner/standard_task_runner.py", line 85, in _start_by_fork
    args.func(args, dag=self.dag)
  File "/home/airflow/.local/lib/python3.8/site-packages/airflow/cli/cli_parser.py", line 48, in command
    return func(*args, **kwargs)
  File "/home/airflow/.local/lib/python3.8/site-packages/airflow/utils/cli.py", line 92, in wrapper
    return f(*args, **kwargs)
  File "/home/airflow/.local/lib/python3.8/site-packages/airflow/cli/commands/task_command.py", line 292, in task_run
    _run_task_by_selected_method(args, dag, ti)
  File "/home/airflow/.local/lib/python3.8/site-packages/airflow/cli/commands/task_command.py", line 107, in _run_task_by_selected_method
    _run_raw_task(args, ti)
  File "/home/airflow/.local/lib/python3.8/site-packages/airflow/cli/commands/task_command.py", line 180, in _run_raw_task
    ti._run_raw_task(
  File "/home/airflow/.local/lib/python3.8/site-packages/airflow/utils/session.py", line 70, in wrapper
    return func(*args, session=session, **kwargs)
  File "/home/airflow/.local/lib/python3.8/site-packages/airflow/models/taskinstance.py", line 1375, in _run_raw_task
    self.handle_failure(e, test_mode, error_file=error_file, session=session)
  File "/home/airflow/.local/lib/python3.8/site-packages/airflow/utils/session.py", line 67, in wrapper
    return func(*args, **kwargs)
  File "/home/airflow/.local/lib/python3.8/site-packages/airflow/models/taskinstance.py", line 1743, in handle_failure
    session.flush()
  File "/home/airflow/.local/lib/python3.8/site-packages/sqlalchemy/orm/session.py", line 2540, in flush
    self._flush(objects)
  File "/home/airflow/.local/lib/python3.8/site-packages/sqlalchemy/orm/session.py", line 2682, in _flush
    transaction.rollback(_capture_exception=True)
  File "/home/airflow/.local/lib/python3.8/site-packages/sqlalchemy/util/langhelpers.py", line 68, in __exit__
    compat.raise_(
  File "/home/airflow/.local/lib/python3.8/site-packages/sqlalchemy/util/compat.py", line 182, in raise_
    raise exception
  File "/home/airflow/.local/lib/python3.8/site-packages/sqlalchemy/orm/session.py", line 2642, in _flush
    flush_context.execute()
  File "/home/airflow/.local/lib/python3.8/site-packages/sqlalchemy/orm/unitofwork.py", line 422, in execute
    rec.execute(self)
  File "/home/airflow/.local/lib/python3.8/site-packages/sqlalchemy/orm/unitofwork.py", line 586, in execute
    persistence.save_obj(
  File "/home/airflow/.local/lib/python3.8/site-packages/sqlalchemy/orm/persistence.py", line 239, in save_obj
    _emit_insert_statements(
  File "/home/airflow/.local/lib/python3.8/site-packages/sqlalchemy/orm/persistence.py", line 1135, in _emit_insert_statements
    result = cached_connections[connection].execute(
  File "/home/airflow/.local/lib/python3.8/site-packages/sqlalchemy/engine/base.py", line 1011, in execute
    return meth(self, multiparams, params)
  File "/home/airflow/.local/lib/python3.8/site-packages/sqlalchemy/sql/elements.py", line 298, in _execute_on_connection
    return connection._execute_clauseelement(self, multiparams, params)
  File "/home/airflow/.local/lib/python3.8/site-packages/sqlalchemy/engine/base.py", line 1124, in _execute_clauseelement
    ret = self._execute_context(
  File "/home/airflow/.local/lib/python3.8/site-packages/sqlalchemy/engine/base.py", line 1316, in _execute_context
    self._handle_dbapi_exception(
  File "/home/airflow/.local/lib/python3.8/site-packages/sqlalchemy/engine/base.py", line 1510, in _handle_dbapi_exception
    util.raise_(
  File "/home/airflow/.local/lib/python3.8/site-packages/sqlalchemy/util/compat.py", line 182, in raise_
    raise exception
  File "/home/airflow/.local/lib/python3.8/site-packages/sqlalchemy/engine/base.py", line 1276, in _execute_context
    self.dialect.do_execute(
  File "/home/airflow/.local/lib/python3.8/site-packages/sqlalchemy/engine/default.py", line 608, in do_execute
    cursor.execute(statement, parameters)
sqlalchemy.exc.ProgrammingError: (psycopg2.errors.UndefinedColumn) column "execution_date" of relation "task_fail" does not exist
LINE 1: INSERT INTO task_fail (task_id, dag_id, execution_date, star...
                                                ^

[SQL: INSERT INTO task_fail (task_id, dag_id, execution_date, start_date, end_date, duration) VALUES (%(task_id)s, %(dag_id)s, %(execution_date)s, %(start_date)s, %(end_date)s, %(duration)s) RETURNING task_fail.id]
[parameters: {'task_id': 'test_import_scikit_learn', 'dag_id': 'external_package_dag', 'execution_date': datetime.datetime(2023, 11, 7, 10, 29, 22, 534602, tzinfo=Timezone('UTC')), 'start_date': datetime.datetime(2023, 11, 7, 10, 29, 23, 978611, tzinfo=Timezone('UTC')), 'end_date': datetime.datetime(2023, 11, 7, 10, 29, 24, 188174, tzinfo=Timezone('UTC')), 'duration': 0}]
(Background on this error at: http://sqlalche.me/e/13/f405)
[2023-11-07 10:29:24,207] {standard_task_runner.py:77} INFO - Job 361: Subtask test_import_scikit_learn
[2023-11-07 10:29:24,222] {local_task_job.py:154} INFO - Task exited with return code 1
[2023-11-07 10:29:24,263] {taskinstance.py:1270} INFO - Marking task as UP_FOR_RETRY. dag_id=external_package_dag, task_id=test_import_scikit_learn, execution_date=20231107T102922, start_date=20231107T102923, end_date=20231107T102924
[2023-11-07 10:29:24,274] {logging_mixin.py:109} INFO - Running <TaskInstance: external_package_dag.test_import_scikit_learn scheduled__2023-11-06T00:00:00+00:00 [running]> on host 108321174b30
[2023-11-07 10:29:24,341] {taskinstance.py:1686} ERROR - Task failed with exception
Traceback (most recent call last):
  File "/home/airflow/.local/lib/python3.8/site-packages/sqlalchemy/engine/base.py", line 1276, in _execute_context
    self.dialect.do_execute(
  File "/home/airflow/.local/lib/python3.8/site-packages/sqlalchemy/engine/default.py", line 608, in do_execute
    cursor.execute(statement, parameters)
psycopg2.errors.UndefinedColumn: column xcom.execution_date does not exist
LINE 1: ...AND xcom.task_id = 'test_import_scikit_learn' AND xcom.execu...
                                                             ^


The above exception was the direct cause of the following exception:

Traceback (most recent call last):
  File "/home/airflow/.local/lib/python3.8/site-packages/airflow/models/taskinstance.py", line 1324, in _run_raw_task
    self._execute_task_with_callbacks(context)
  File "/home/airflow/.local/lib/python3.8/site-packages/airflow/models/taskinstance.py", line 1403, in _execute_task_with_callbacks
    self.clear_xcom_data()
  File "/home/airflow/.local/lib/python3.8/site-packages/airflow/utils/session.py", line 70, in wrapper
    return func(*args, session=session, **kwargs)
  File "/home/airflow/.local/lib/python3.8/site-packages/airflow/models/taskinstance.py", line 791, in clear_xcom_data
    XCom.clear(
  File "/home/airflow/.local/lib/python3.8/site-packages/airflow/utils/session.py", line 67, in wrapper
    return func(*args, **kwargs)
  File "/home/airflow/.local/lib/python3.8/site-packages/airflow/models/xcom.py", line 322, in clear
    return query.delete()
  File "/home/airflow/.local/lib/python3.8/site-packages/sqlalchemy/orm/query.py", line 3926, in delete
    delete_op.exec_()
  File "/home/airflow/.local/lib/python3.8/site-packages/sqlalchemy/orm/persistence.py", line 1697, in exec_
    self._do_exec()
  File "/home/airflow/.local/lib/python3.8/site-packages/sqlalchemy/orm/persistence.py", line 1930, in _do_exec
    self._execute_stmt(delete_stmt)
  File "/home/airflow/.local/lib/python3.8/site-packages/sqlalchemy/orm/persistence.py", line 1702, in _execute_stmt
    self.result = self.query._execute_crud(stmt, self.mapper)
  File "/home/airflow/.local/lib/python3.8/site-packages/sqlalchemy/orm/query.py", line 3568, in _execute_crud
    return conn.execute(stmt, self._params)
  File "/home/airflow/.local/lib/python3.8/site-packages/sqlalchemy/engine/base.py", line 1011, in execute
    return meth(self, multiparams, params)
  File "/home/airflow/.local/lib/python3.8/site-packages/sqlalchemy/sql/elements.py", line 298, in _execute_on_connection
    return connection._execute_clauseelement(self, multiparams, params)
  File "/home/airflow/.local/lib/python3.8/site-packages/sqlalchemy/engine/base.py", line 1124, in _execute_clauseelement
    ret = self._execute_context(
  File "/home/airflow/.local/lib/python3.8/site-packages/sqlalchemy/engine/base.py", line 1316, in _execute_context
    self._handle_dbapi_exception(
  File "/home/airflow/.local/lib/python3.8/site-packages/sqlalchemy/engine/base.py", line 1510, in _handle_dbapi_exception
    util.raise_(
  File "/home/airflow/.local/lib/python3.8/site-packages/sqlalchemy/util/compat.py", line 182, in raise_
    raise exception
  File "/home/airflow/.local/lib/python3.8/site-packages/sqlalchemy/engine/base.py", line 1276, in _execute_context
    self.dialect.do_execute(
  File "/home/airflow/.local/lib/python3.8/site-packages/sqlalchemy/engine/default.py", line 608, in do_execute
    cursor.execute(statement, parameters)
sqlalchemy.exc.ProgrammingError: (psycopg2.errors.UndefinedColumn) column xcom.execution_date does not exist
LINE 1: ...AND xcom.task_id = 'test_import_scikit_learn' AND xcom.execu...
                                                             ^

[SQL: DELETE FROM xcom WHERE xcom.dag_id = %(dag_id_1)s AND xcom.task_id = %(task_id_1)s AND xcom.execution_date = %(execution_date_1)s]
[parameters: {'dag_id_1': 'external_package_dag', 'task_id_1': 'test_import_scikit_learn', 'execution_date_1': datetime.datetime(2023, 11, 6, 0, 0, tzinfo=Timezone('UTC'))}]
(Background on this error at: http://sqlalche.me/e/13/f405)
[2023-11-07 10:29:24,362] {taskinstance.py:1270} INFO - Marking task as UP_FOR_RETRY. dag_id=external_package_dag, task_id=test_import_scikit_learn, execution_date=20231106T000000, start_date=20231107T102924, end_date=20231107T102924
[2023-11-07 10:29:24,376] {standard_task_runner.py:88} ERROR - Failed to execute job 361 for task test_import_scikit_learn
Traceback (most recent call last):
  File "/home/airflow/.local/lib/python3.8/site-packages/sqlalchemy/engine/base.py", line 1276, in _execute_context
    self.dialect.do_execute(
  File "/home/airflow/.local/lib/python3.8/site-packages/sqlalchemy/engine/default.py", line 608, in do_execute
    cursor.execute(statement, parameters)
psycopg2.errors.UndefinedColumn: column xcom.execution_date does not exist
LINE 1: ...AND xcom.task_id = 'test_import_scikit_learn' AND xcom.execu...
                                                             ^


The above exception was the direct cause of the following exception:

Traceback (most recent call last):
  File "/home/airflow/.local/lib/python3.8/site-packages/airflow/models/taskinstance.py", line 1324, in _run_raw_task
    self._execute_task_with_callbacks(context)
  File "/home/airflow/.local/lib/python3.8/site-packages/airflow/models/taskinstance.py", line 1403, in _execute_task_with_callbacks
    self.clear_xcom_data()
  File "/home/airflow/.local/lib/python3.8/site-packages/airflow/utils/session.py", line 70, in wrapper
    return func(*args, session=session, **kwargs)
  File "/home/airflow/.local/lib/python3.8/site-packages/airflow/models/taskinstance.py", line 791, in clear_xcom_data
    XCom.clear(
  File "/home/airflow/.local/lib/python3.8/site-packages/airflow/utils/session.py", line 67, in wrapper
    return func(*args, **kwargs)
  File "/home/airflow/.local/lib/python3.8/site-packages/airflow/models/xcom.py", line 322, in clear
    return query.delete()
  File "/home/airflow/.local/lib/python3.8/site-packages/sqlalchemy/orm/query.py", line 3926, in delete
    delete_op.exec_()
  File "/home/airflow/.local/lib/python3.8/site-packages/sqlalchemy/orm/persistence.py", line 1697, in exec_
    self._do_exec()
  File "/home/airflow/.local/lib/python3.8/site-packages/sqlalchemy/orm/persistence.py", line 1930, in _do_exec
    self._execute_stmt(delete_stmt)
  File "/home/airflow/.local/lib/python3.8/site-packages/sqlalchemy/orm/persistence.py", line 1702, in _execute_stmt
    self.result = self.query._execute_crud(stmt, self.mapper)
  File "/home/airflow/.local/lib/python3.8/site-packages/sqlalchemy/orm/query.py", line 3568, in _execute_crud
    return conn.execute(stmt, self._params)
  File "/home/airflow/.local/lib/python3.8/site-packages/sqlalchemy/engine/base.py", line 1011, in execute
    return meth(self, multiparams, params)
  File "/home/airflow/.local/lib/python3.8/site-packages/sqlalchemy/sql/elements.py", line 298, in _execute_on_connection
    return connection._execute_clauseelement(self, multiparams, params)
  File "/home/airflow/.local/lib/python3.8/site-packages/sqlalchemy/engine/base.py", line 1124, in _execute_clauseelement
    ret = self._execute_context(
  File "/home/airflow/.local/lib/python3.8/site-packages/sqlalchemy/engine/base.py", line 1316, in _execute_context
    self._handle_dbapi_exception(
  File "/home/airflow/.local/lib/python3.8/site-packages/sqlalchemy/engine/base.py", line 1510, in _handle_dbapi_exception
    util.raise_(
  File "/home/airflow/.local/lib/python3.8/site-packages/sqlalchemy/util/compat.py", line 182, in raise_
    raise exception
  File "/home/airflow/.local/lib/python3.8/site-packages/sqlalchemy/engine/base.py", line 1276, in _execute_context
    self.dialect.do_execute(
  File "/home/airflow/.local/lib/python3.8/site-packages/sqlalchemy/engine/default.py", line 608, in do_execute
    cursor.execute(statement, parameters)
sqlalchemy.exc.ProgrammingError: (psycopg2.errors.UndefinedColumn) column xcom.execution_date does not exist
LINE 1: ...AND xcom.task_id = 'test_import_scikit_learn' AND xcom.execu...
                                                             ^

[SQL: DELETE FROM xcom WHERE xcom.dag_id = %(dag_id_1)s AND xcom.task_id = %(task_id_1)s AND xcom.execution_date = %(execution_date_1)s]
[parameters: {'dag_id_1': 'external_package_dag', 'task_id_1': 'test_import_scikit_learn', 'execution_date_1': datetime.datetime(2023, 11, 6, 0, 0, tzinfo=Timezone('UTC'))}]
(Background on this error at: http://sqlalche.me/e/13/f405)

During handling of the above exception, another exception occurred:

Traceback (most recent call last):
  File "/home/airflow/.local/lib/python3.8/site-packages/sqlalchemy/engine/base.py", line 1276, in _execute_context
    self.dialect.do_execute(
  File "/home/airflow/.local/lib/python3.8/site-packages/sqlalchemy/engine/default.py", line 608, in do_execute
    cursor.execute(statement, parameters)
psycopg2.errors.UndefinedColumn: column "execution_date" of relation "task_fail" does not exist
LINE 1: INSERT INTO task_fail (task_id, dag_id, execution_date, star...
                                                ^


The above exception was the direct cause of the following exception:

Traceback (most recent call last):
  File "/home/airflow/.local/lib/python3.8/site-packages/airflow/task/task_runner/standard_task_runner.py", line 85, in _start_by_fork
    args.func(args, dag=self.dag)
  File "/home/airflow/.local/lib/python3.8/site-packages/airflow/cli/cli_parser.py", line 48, in command
    return func(*args, **kwargs)
  File "/home/airflow/.local/lib/python3.8/site-packages/airflow/utils/cli.py", line 92, in wrapper
    return f(*args, **kwargs)
  File "/home/airflow/.local/lib/python3.8/site-packages/airflow/cli/commands/task_command.py", line 292, in task_run
    _run_task_by_selected_method(args, dag, ti)
  File "/home/airflow/.local/lib/python3.8/site-packages/airflow/cli/commands/task_command.py", line 107, in _run_task_by_selected_method
    _run_raw_task(args, ti)
  File "/home/airflow/.local/lib/python3.8/site-packages/airflow/cli/commands/task_command.py", line 180, in _run_raw_task
    ti._run_raw_task(
  File "/home/airflow/.local/lib/python3.8/site-packages/airflow/utils/session.py", line 70, in wrapper
    return func(*args, session=session, **kwargs)
  File "/home/airflow/.local/lib/python3.8/site-packages/airflow/models/taskinstance.py", line 1375, in _run_raw_task
    self.handle_failure(e, test_mode, error_file=error_file, session=session)
  File "/home/airflow/.local/lib/python3.8/site-packages/airflow/utils/session.py", line 67, in wrapper
    return func(*args, **kwargs)
  File "/home/airflow/.local/lib/python3.8/site-packages/airflow/models/taskinstance.py", line 1743, in handle_failure
    session.flush()
  File "/home/airflow/.local/lib/python3.8/site-packages/sqlalchemy/orm/session.py", line 2540, in flush
    self._flush(objects)
  File "/home/airflow/.local/lib/python3.8/site-packages/sqlalchemy/orm/session.py", line 2682, in _flush
    transaction.rollback(_capture_exception=True)
  File "/home/airflow/.local/lib/python3.8/site-packages/sqlalchemy/util/langhelpers.py", line 68, in __exit__
    compat.raise_(
  File "/home/airflow/.local/lib/python3.8/site-packages/sqlalchemy/util/compat.py", line 182, in raise_
    raise exception
  File "/home/airflow/.local/lib/python3.8/site-packages/sqlalchemy/orm/session.py", line 2642, in _flush
    flush_context.execute()
  File "/home/airflow/.local/lib/python3.8/site-packages/sqlalchemy/orm/unitofwork.py", line 422, in execute
    rec.execute(self)
  File "/home/airflow/.local/lib/python3.8/site-packages/sqlalchemy/orm/unitofwork.py", line 586, in execute
    persistence.save_obj(
  File "/home/airflow/.local/lib/python3.8/site-packages/sqlalchemy/orm/persistence.py", line 239, in save_obj
    _emit_insert_statements(
  File "/home/airflow/.local/lib/python3.8/site-packages/sqlalchemy/orm/persistence.py", line 1135, in _emit_insert_statements
    result = cached_connections[connection].execute(
  File "/home/airflow/.local/lib/python3.8/site-packages/sqlalchemy/engine/base.py", line 1011, in execute
    return meth(self, multiparams, params)
  File "/home/airflow/.local/lib/python3.8/site-packages/sqlalchemy/sql/elements.py", line 298, in _execute_on_connection
    return connection._execute_clauseelement(self, multiparams, params)
  File "/home/airflow/.local/lib/python3.8/site-packages/sqlalchemy/engine/base.py", line 1124, in _execute_clauseelement
    ret = self._execute_context(
  File "/home/airflow/.local/lib/python3.8/site-packages/sqlalchemy/engine/base.py", line 1316, in _execute_context
    self._handle_dbapi_exception(
  File "/home/airflow/.local/lib/python3.8/site-packages/sqlalchemy/engine/base.py", line 1510, in _handle_dbapi_exception
    util.raise_(
  File "/home/airflow/.local/lib/python3.8/site-packages/sqlalchemy/util/compat.py", line 182, in raise_
    raise exception
  File "/home/airflow/.local/lib/python3.8/site-packages/sqlalchemy/engine/base.py", line 1276, in _execute_context
    self.dialect.do_execute(
  File "/home/airflow/.local/lib/python3.8/site-packages/sqlalchemy/engine/default.py", line 608, in do_execute
    cursor.execute(statement, parameters)
sqlalchemy.exc.ProgrammingError: (psycopg2.errors.UndefinedColumn) column "execution_date" of relation "task_fail" does not exist
LINE 1: INSERT INTO task_fail (task_id, dag_id, execution_date, star...
                                                ^

[SQL: INSERT INTO task_fail (task_id, dag_id, execution_date, start_date, end_date, duration) VALUES (%(task_id)s, %(dag_id)s, %(execution_date)s, %(start_date)s, %(end_date)s, %(duration)s) RETURNING task_fail.id]
[parameters: {'task_id': 'test_import_scikit_learn', 'dag_id': 'external_package_dag', 'execution_date': datetime.datetime(2023, 11, 6, 0, 0, tzinfo=Timezone('UTC')), 'start_date': datetime.datetime(2023, 11, 7, 10, 29, 24, 146615, tzinfo=Timezone('UTC')), 'end_date': datetime.datetime(2023, 11, 7, 10, 29, 24, 362095, tzinfo=Timezone('UTC')), 'duration': 0}]
(Background on this error at: http://sqlalche.me/e/13/f405)
[2023-11-07 10:29:24,417] {local_task_job.py:154} INFO - Task exited with return code 1
[2023-11-07 10:29:24,446] {taskinstance.py:1270} INFO - Marking task as UP_FOR_RETRY. dag_id=external_package_dag, task_id=test_import_scikit_learn, execution_date=20231106T000000, start_date=20231107T102924, end_date=20231107T102924
