[2023-11-07T13:32:21.224+0000] {taskinstance.py:1159} INFO - Dependencies all met for dep_context=non-requeueable deps ti=<TaskInstance: package_dag.task_a manual__2023-11-07T13:32:20.336290+00:00 [queued]>
[2023-11-07T13:32:21.238+0000] {taskinstance.py:1159} INFO - Dependencies all met for dep_context=requeueable deps ti=<TaskInstance: package_dag.task_a manual__2023-11-07T13:32:20.336290+00:00 [queued]>
[2023-11-07T13:32:21.239+0000] {taskinstance.py:1361} INFO - Starting attempt 1 of 3
[2023-11-07T13:32:21.262+0000] {taskinstance.py:1382} INFO - Executing <Task(PythonOperator): task_a> on 2023-11-07 13:32:20.336290+00:00
[2023-11-07T13:32:21.268+0000] {standard_task_runner.py:57} INFO - Started process 418 to run task
[2023-11-07T13:32:21.274+0000] {standard_task_runner.py:84} INFO - Running: ['***', 'tasks', 'run', 'package_dag', 'task_a', 'manual__2023-11-07T13:32:20.336290+00:00', '--job-id', '34', '--raw', '--subdir', 'DAGS_FOLDER/external_package_dag.py', '--cfg-path', '/tmp/tmpu1wx89f9']
[2023-11-07T13:32:21.278+0000] {standard_task_runner.py:85} INFO - Job 34: Subtask task_a
[2023-11-07T13:32:21.351+0000] {task_command.py:416} INFO - Running <TaskInstance: package_dag.task_a manual__2023-11-07T13:32:20.336290+00:00 [running]> on host 4d67d0455c8b
[2023-11-07T13:32:21.504+0000] {taskinstance.py:1662} INFO - Exporting env vars: AIRFLOW_CTX_DAG_OWNER='safarnejad' AIRFLOW_CTX_DAG_ID='package_dag' AIRFLOW_CTX_TASK_ID='task_a' AIRFLOW_CTX_EXECUTION_DATE='2023-11-07T13:32:20.336290+00:00' AIRFLOW_CTX_TRY_NUMBER='1' AIRFLOW_CTX_DAG_RUN_ID='manual__2023-11-07T13:32:20.336290+00:00'
[2023-11-07T13:32:21.509+0000] {taskinstance.py:1937} ERROR - Task failed with exception
Traceback (most recent call last):
  File "/home/airflow/.local/lib/python3.8/site-packages/airflow/operators/python.py", line 192, in execute
    return_value = self.execute_callable()
  File "/home/airflow/.local/lib/python3.8/site-packages/airflow/operators/python.py", line 209, in execute_callable
    return self.python_callable(*self.op_args, **self.op_kwargs)
  File "/opt/airflow/dags/external_package_dag.py", line 8, in check_version
    import sklearn
ModuleNotFoundError: No module named 'sklearn'
[2023-11-07T13:32:21.541+0000] {taskinstance.py:1400} INFO - Marking task as UP_FOR_RETRY. dag_id=package_dag, task_id=task_a, execution_date=20231107T133220, start_date=20231107T133221, end_date=20231107T133221
[2023-11-07T13:32:21.579+0000] {standard_task_runner.py:104} ERROR - Failed to execute job 34 for task task_a (No module named 'sklearn'; 418)
[2023-11-07T13:32:21.611+0000] {local_task_job_runner.py:228} INFO - Task exited with return code 1
[2023-11-07T13:32:21.648+0000] {taskinstance.py:2778} INFO - 0 downstream tasks scheduled from follow-on schedule check
