[2023-11-06T12:08:05.423+0000] {taskinstance.py:1159} INFO - Dependencies all met for dep_context=non-requeueable deps ti=<TaskInstance: catchup_and_backfill_dag.task_a scheduled__2023-10-22T00:00:00+00:00 [queued]>
[2023-11-06T12:08:05.441+0000] {taskinstance.py:1159} INFO - Dependencies all met for dep_context=requeueable deps ti=<TaskInstance: catchup_and_backfill_dag.task_a scheduled__2023-10-22T00:00:00+00:00 [queued]>
[2023-11-06T12:08:05.443+0000] {taskinstance.py:1361} INFO - Starting attempt 2 of 2
[2023-11-06T12:08:05.601+0000] {taskinstance.py:1382} INFO - Executing <Task(BashOperator): task_a> on 2023-10-22 00:00:00+00:00
[2023-11-06T12:08:05.638+0000] {standard_task_runner.py:57} INFO - Started process 1014 to run task
[2023-11-06T12:08:05.657+0000] {standard_task_runner.py:84} INFO - Running: ['***', 'tasks', 'run', 'catchup_and_backfill_dag', 'task_a', 'scheduled__2023-10-22T00:00:00+00:00', '--job-id', '112', '--raw', '--subdir', 'DAGS_FOLDER/catchup_and_backfill_dag.py', '--cfg-path', '/tmp/tmpy7c_4tm1']
[2023-11-06T12:08:05.665+0000] {standard_task_runner.py:85} INFO - Job 112: Subtask task_a
[2023-11-06T12:08:05.843+0000] {task_command.py:416} INFO - Running <TaskInstance: catchup_and_backfill_dag.task_a scheduled__2023-10-22T00:00:00+00:00 [running]> on host cf1baac588aa
[2023-11-06T12:08:06.065+0000] {taskinstance.py:1662} INFO - Exporting env vars: AIRFLOW_CTX_DAG_OWNER='safarnejad' AIRFLOW_CTX_DAG_ID='catchup_and_backfill_dag' AIRFLOW_CTX_TASK_ID='task_a' AIRFLOW_CTX_EXECUTION_DATE='2023-10-22T00:00:00+00:00' AIRFLOW_CTX_TRY_NUMBER='2' AIRFLOW_CTX_DAG_RUN_ID='scheduled__2023-10-22T00:00:00+00:00'
[2023-11-06T12:08:06.070+0000] {subprocess.py:63} INFO - Tmp dir root location: /tmp
[2023-11-06T12:08:06.071+0000] {subprocess.py:75} INFO - Running command: ['/bin/bash', '-c', 'echo Hello World :)']
[2023-11-06T12:08:06.097+0000] {subprocess.py:86} INFO - Output:
[2023-11-06T12:08:06.102+0000] {subprocess.py:93} INFO - /bin/bash: -c: line 1: syntax error near unexpected token `)'
[2023-11-06T12:08:06.103+0000] {subprocess.py:93} INFO - /bin/bash: -c: line 1: `echo Hello World :)'
[2023-11-06T12:08:06.104+0000] {subprocess.py:97} INFO - Command exited with return code 2
[2023-11-06T12:08:06.129+0000] {taskinstance.py:1937} ERROR - Task failed with exception
Traceback (most recent call last):
  File "/home/airflow/.local/lib/python3.8/site-packages/airflow/operators/bash.py", line 210, in execute
    raise AirflowException(
airflow.exceptions.AirflowException: Bash command failed. The command returned a non-zero exit code 2.
[2023-11-06T12:08:06.139+0000] {taskinstance.py:1400} INFO - Marking task as FAILED. dag_id=catchup_and_backfill_dag, task_id=task_a, execution_date=20231022T000000, start_date=20231106T120805, end_date=20231106T120806
[2023-11-06T12:08:06.297+0000] {standard_task_runner.py:104} ERROR - Failed to execute job 112 for task task_a (Bash command failed. The command returned a non-zero exit code 2.; 1014)
[2023-11-06T12:08:06.337+0000] {local_task_job_runner.py:228} INFO - Task exited with return code 1
[2023-11-06T12:08:06.383+0000] {taskinstance.py:2778} INFO - 0 downstream tasks scheduled from follow-on schedule check
