[2023-11-07T13:11:24.668+0000] {taskinstance.py:1159} INFO - Dependencies all met for dep_context=non-requeueable deps ti=<TaskInstance: package_dag.task_a manual__2023-11-07T13:10:22.103954+00:00 [queued]>
[2023-11-07T13:11:24.685+0000] {taskinstance.py:1159} INFO - Dependencies all met for dep_context=requeueable deps ti=<TaskInstance: package_dag.task_a manual__2023-11-07T13:10:22.103954+00:00 [queued]>
[2023-11-07T13:11:24.686+0000] {taskinstance.py:1361} INFO - Starting attempt 2 of 3
[2023-11-07T13:11:24.719+0000] {taskinstance.py:1382} INFO - Executing <Task(PythonOperator): task_a> on 2023-11-07 13:10:22.103954+00:00
[2023-11-07T13:11:24.727+0000] {standard_task_runner.py:57} INFO - Started process 424 to run task
[2023-11-07T13:11:24.733+0000] {standard_task_runner.py:84} INFO - Running: ['***', 'tasks', 'run', 'package_dag', 'task_a', 'manual__2023-11-07T13:10:22.103954+00:00', '--job-id', '4', '--raw', '--subdir', 'DAGS_FOLDER/external_package_dag.py', '--cfg-path', '/tmp/tmppov60fd0']
[2023-11-07T13:11:24.739+0000] {standard_task_runner.py:85} INFO - Job 4: Subtask task_a
[2023-11-07T13:11:24.849+0000] {task_command.py:416} INFO - Running <TaskInstance: package_dag.task_a manual__2023-11-07T13:10:22.103954+00:00 [running]> on host 33d2bcd227f6
[2023-11-07T13:11:25.029+0000] {taskinstance.py:1662} INFO - Exporting env vars: AIRFLOW_CTX_DAG_OWNER='safarnejad' AIRFLOW_CTX_DAG_ID='package_dag' AIRFLOW_CTX_TASK_ID='task_a' AIRFLOW_CTX_EXECUTION_DATE='2023-11-07T13:10:22.103954+00:00' AIRFLOW_CTX_TRY_NUMBER='2' AIRFLOW_CTX_DAG_RUN_ID='manual__2023-11-07T13:10:22.103954+00:00'
[2023-11-07T13:11:25.038+0000] {taskinstance.py:1937} ERROR - Task failed with exception
Traceback (most recent call last):
  File "/home/airflow/.local/lib/python3.8/site-packages/airflow/operators/python.py", line 192, in execute
    return_value = self.execute_callable()
  File "/home/airflow/.local/lib/python3.8/site-packages/airflow/operators/python.py", line 209, in execute_callable
    return self.python_callable(*self.op_args, **self.op_kwargs)
  File "/opt/airflow/dags/external_package_dag.py", line 8, in check_version
    import sklearn
ModuleNotFoundError: No module named 'sklearn'
[2023-11-07T13:11:25.056+0000] {taskinstance.py:1400} INFO - Marking task as UP_FOR_RETRY. dag_id=package_dag, task_id=task_a, execution_date=20231107T131022, start_date=20231107T131124, end_date=20231107T131125
[2023-11-07T13:11:25.083+0000] {standard_task_runner.py:104} ERROR - Failed to execute job 4 for task task_a (No module named 'sklearn'; 424)
[2023-11-07T13:11:25.112+0000] {local_task_job_runner.py:228} INFO - Task exited with return code 1
[2023-11-07T13:11:25.145+0000] {taskinstance.py:2778} INFO - 0 downstream tasks scheduled from follow-on schedule check
